{
 "cells": [
  {
   "cell_type": "code",
   "execution_count": 2,
   "id": "02edbc91-afc5-4efa-b826-69befcbb4eaf",
   "metadata": {},
   "outputs": [],
   "source": [
    "import tensorflow as tf\n",
    "from tensorflow import keras\n",
    "import numpy as np\n",
    "import matplotlib.pyplot as plt\n",
    "from sklearn.model_selection import train_test_split"
   ]
  },
  {
   "cell_type": "code",
   "execution_count": 4,
   "id": "1c76392b-3de5-4131-8007-29898a15639c",
   "metadata": {},
   "outputs": [
    {
     "name": "stdout",
     "output_type": "stream",
     "text": [
      "MNIST Veri Seti Yükleniyor\n",
      "Downloading data from https://storage.googleapis.com/tensorflow/tf-keras-datasets/mnist.npz\n",
      "11490434/11490434 [==============================] - 75s 7us/step\n"
     ]
    }
   ],
   "source": [
    "print(\"MNIST Veri Seti Yükleniyor\")\n",
    "(x_train, y_train) , (x_test, y_test) = keras.datasets.mnist.load_data()"
   ]
  },
  {
   "cell_type": "code",
   "execution_count": 6,
   "id": "718ef44b-0c5f-49a3-9c10-11940b7479f9",
   "metadata": {},
   "outputs": [
    {
     "name": "stdout",
     "output_type": "stream",
     "text": [
      "Eğitim Verilerinin boyutu ve sayısı = (60000, 28, 28, 1)\n",
      "Test Verilerinin boyutu ve sayısı = (10000, 28, 28, 1)\n"
     ]
    }
   ],
   "source": [
    "x_train = x_train.reshape(-1,28,28,1)\n",
    "x_test = x_test.reshape(-1,28,28,1)\n",
    "x_train = x_train.astype('float32')/255.0\n",
    "x_test = x_test.astype('float32')/255.0\n",
    "print(f\"Eğitim Verilerinin boyutu ve sayısı = {x_train.shape}\")\n",
    "print(f\"Test Verilerinin boyutu ve sayısı = {x_test.shape}\")"
   ]
  },
  {
   "cell_type": "code",
   "execution_count": 8,
   "id": "cfa12261-1097-4e33-b738-fa126cca3309",
   "metadata": {},
   "outputs": [],
   "source": [
    "y_train = keras.utils.to_categorical(y_train, 10)\n",
    "y_test = keras.utils.to_categorical(y_test, 10)"
   ]
  },
  {
   "cell_type": "code",
   "execution_count": 26,
   "id": "82f55a55-9ef1-4008-9e6f-c953221a41b0",
   "metadata": {},
   "outputs": [
    {
     "name": "stdout",
     "output_type": "stream",
     "text": [
      "Veri Bölme Sonrası Boyutları\n",
      "Eğitim Verisi Boyutu: (48000, 28, 28, 1)\n",
      "Validation Verisi Boyutu: (12000, 28, 28, 1)\n"
     ]
    }
   ],
   "source": [
    "X_train, X_val, y_train_split, y_val = train_test_split(\n",
    "    x_train,\n",
    "    y_train,\n",
    "    test_size=0.2,\n",
    "    random_state=42,\n",
    "    stratify=y_train\n",
    ")\n",
    "print(f\"Veri Bölme Sonrası Boyutları\")\n",
    "print(f\"Eğitim Verisi Boyutu: {X_train.shape}\")\n",
    "print(f\"Validation Verisi Boyutu: {X_val.shape}\")"
   ]
  },
  {
   "cell_type": "code",
   "execution_count": 49,
   "id": "c2be1c56-c34a-47ec-bf90-24428672ea9a",
   "metadata": {},
   "outputs": [],
   "source": [
    "model = keras.Sequential([\n",
    "    keras.layers.Conv2D(32, (3,3), activation='relu', input_shape=(28,28,1)),\n",
    "    keras.layers.BatchNormalization(),\n",
    "    keras.layers.Conv2D(32, (3,3), activation='relu'),\n",
    "    keras.layers.BatchNormalization(),\n",
    "    keras.layers.MaxPooling2D((2,2)),\n",
    "    keras.layers.Dropout(0,25),\n",
    "\n",
    "    keras.layers.Conv2D(64, (3,3), activation='relu', input_shape=(28,28,1)),\n",
    "    keras.layers.BatchNormalization(),\n",
    "    keras.layers.Conv2D(64, (3,3), activation='relu'),\n",
    "    keras.layers.BatchNormalization(),\n",
    "    keras.layers.MaxPooling2D((2,2)),\n",
    "    keras.layers.Dropout(0,25),\n",
    "\n",
    "    keras.layers.Flatten(),\n",
    "    keras.layers.Dense(512, activation='relu'),\n",
    "    keras.layers.BatchNormalization(),\n",
    "    keras.layers.Dropout(0,5),\n",
    "    keras.layers.Dense(10, activation='softmax')\n",
    "    \n",
    "])\n"
   ]
  },
  {
   "cell_type": "code",
   "execution_count": 51,
   "id": "df240a18-6a82-4c42-bebf-ccc951a625d0",
   "metadata": {},
   "outputs": [],
   "source": [
    "model.compile(\n",
    "    optimizer='adam',\n",
    "    loss='categorical_crossentropy',\n",
    "    metrics=['accuracy']\n",
    ")"
   ]
  },
  {
   "cell_type": "code",
   "execution_count": 53,
   "id": "1c29e62c-6536-4998-b8f0-a2f774420cc8",
   "metadata": {},
   "outputs": [],
   "source": [
    "model_checkpoint = keras.callbacks.ModelCheckpoint(\n",
    "    'two_blocks_cnn_for_mnist_dataset.h5',\n",
    "    monitor='val_accuracy',\n",
    "    save_best_only=True,\n",
    "    mode='max', verbase = 1)"
   ]
  },
  {
   "cell_type": "code",
   "execution_count": 59,
   "id": "4ad9fe36-e610-4ad3-91f2-99a8994f8503",
   "metadata": {},
   "outputs": [
    {
     "name": "stdout",
     "output_type": "stream",
     "text": [
      "Epoch 1/5\n"
     ]
    },
    {
     "ename": "TypeError",
     "evalue": "in user code:\n\n    File \"C:\\Users\\Ztyo\\anaconda3\\envs\\env_ybs\\lib\\site-packages\\keras\\engine\\training.py\", line 1051, in train_function  *\n        return step_function(self, iterator)\n    File \"C:\\Users\\Ztyo\\anaconda3\\envs\\env_ybs\\lib\\site-packages\\keras\\engine\\training.py\", line 1040, in step_function  **\n        outputs = model.distribute_strategy.run(run_step, args=(data,))\n    File \"C:\\Users\\Ztyo\\anaconda3\\envs\\env_ybs\\lib\\site-packages\\keras\\engine\\training.py\", line 1030, in run_step  **\n        outputs = model.train_step(data)\n    File \"C:\\Users\\Ztyo\\anaconda3\\envs\\env_ybs\\lib\\site-packages\\keras\\engine\\training.py\", line 889, in train_step\n        y_pred = self(x, training=True)\n    File \"C:\\Users\\Ztyo\\anaconda3\\envs\\env_ybs\\lib\\site-packages\\keras\\utils\\traceback_utils.py\", line 67, in error_handler\n        raise e.with_traceback(filtered_tb) from None\n    File \"C:\\Users\\Ztyo\\anaconda3\\envs\\env_ybs\\lib\\site-packages\\keras\\layers\\regularization\\dropout.py\", line 99, in _get_noise_shape\n        for i, value in enumerate(self.noise_shape):\n\n    TypeError: Exception encountered when calling layer \"dropout_11\" (type Dropout).\n    \n    'int' object is not iterable\n    \n    Call arguments received by layer \"dropout_11\" (type Dropout):\n      • inputs=tf.Tensor(shape=(128, 12, 12, 32), dtype=float32)\n      • training=True\n",
     "output_type": "error",
     "traceback": [
      "\u001b[1;31m---------------------------------------------------------------------------\u001b[0m",
      "\u001b[1;31mTypeError\u001b[0m                                 Traceback (most recent call last)",
      "Cell \u001b[1;32mIn[59], line 1\u001b[0m\n\u001b[1;32m----> 1\u001b[0m \u001b[43mmodel\u001b[49m\u001b[38;5;241;43m.\u001b[39;49m\u001b[43mfit\u001b[49m\u001b[43m(\u001b[49m\u001b[43mX_train\u001b[49m\u001b[43m,\u001b[49m\u001b[43my_train_split\u001b[49m\u001b[43m,\u001b[49m\u001b[43mvalidation_data\u001b[49m\u001b[38;5;241;43m=\u001b[39;49m\u001b[43m(\u001b[49m\u001b[43mX_val\u001b[49m\u001b[43m,\u001b[49m\u001b[43my_val\u001b[49m\u001b[43m)\u001b[49m\u001b[43m,\u001b[49m\n\u001b[0;32m      2\u001b[0m \u001b[43m         \u001b[49m\u001b[43mbatch_size\u001b[49m\u001b[38;5;241;43m=\u001b[39;49m\u001b[38;5;241;43m128\u001b[39;49m\u001b[43m,\u001b[49m\u001b[43m \u001b[49m\u001b[43mepochs\u001b[49m\u001b[38;5;241;43m=\u001b[39;49m\u001b[38;5;241;43m5\u001b[39;49m\u001b[43m,\u001b[49m\u001b[43m \u001b[49m\u001b[43mcallbacks\u001b[49m\u001b[38;5;241;43m=\u001b[39;49m\u001b[43mmodel_checkpoint\u001b[49m\u001b[43m,\u001b[49m\u001b[43mverbose\u001b[49m\u001b[38;5;241;43m=\u001b[39;49m\u001b[38;5;241;43m1\u001b[39;49m\u001b[43m)\u001b[49m\n",
      "File \u001b[1;32m~\\anaconda3\\envs\\env_ybs\\lib\\site-packages\\keras\\utils\\traceback_utils.py:67\u001b[0m, in \u001b[0;36mfilter_traceback.<locals>.error_handler\u001b[1;34m(*args, **kwargs)\u001b[0m\n\u001b[0;32m     65\u001b[0m \u001b[38;5;28;01mexcept\u001b[39;00m \u001b[38;5;167;01mException\u001b[39;00m \u001b[38;5;28;01mas\u001b[39;00m e:  \u001b[38;5;66;03m# pylint: disable=broad-except\u001b[39;00m\n\u001b[0;32m     66\u001b[0m   filtered_tb \u001b[38;5;241m=\u001b[39m _process_traceback_frames(e\u001b[38;5;241m.\u001b[39m__traceback__)\n\u001b[1;32m---> 67\u001b[0m   \u001b[38;5;28;01mraise\u001b[39;00m e\u001b[38;5;241m.\u001b[39mwith_traceback(filtered_tb) \u001b[38;5;28;01mfrom\u001b[39;00m \u001b[38;5;28;01mNone\u001b[39;00m\n\u001b[0;32m     68\u001b[0m \u001b[38;5;28;01mfinally\u001b[39;00m:\n\u001b[0;32m     69\u001b[0m   \u001b[38;5;28;01mdel\u001b[39;00m filtered_tb\n",
      "File \u001b[1;32m~\\AppData\\Local\\Temp\\__autograph_generated_filenm8g2hnw.py:15\u001b[0m, in \u001b[0;36mouter_factory.<locals>.inner_factory.<locals>.tf__train_function\u001b[1;34m(iterator)\u001b[0m\n\u001b[0;32m     13\u001b[0m \u001b[38;5;28;01mtry\u001b[39;00m:\n\u001b[0;32m     14\u001b[0m     do_return \u001b[38;5;241m=\u001b[39m \u001b[38;5;28;01mTrue\u001b[39;00m\n\u001b[1;32m---> 15\u001b[0m     retval_ \u001b[38;5;241m=\u001b[39m ag__\u001b[38;5;241m.\u001b[39mconverted_call(ag__\u001b[38;5;241m.\u001b[39mld(step_function), (ag__\u001b[38;5;241m.\u001b[39mld(\u001b[38;5;28mself\u001b[39m), ag__\u001b[38;5;241m.\u001b[39mld(iterator)), \u001b[38;5;28;01mNone\u001b[39;00m, fscope)\n\u001b[0;32m     16\u001b[0m \u001b[38;5;28;01mexcept\u001b[39;00m:\n\u001b[0;32m     17\u001b[0m     do_return \u001b[38;5;241m=\u001b[39m \u001b[38;5;28;01mFalse\u001b[39;00m\n",
      "\u001b[1;31mTypeError\u001b[0m: in user code:\n\n    File \"C:\\Users\\Ztyo\\anaconda3\\envs\\env_ybs\\lib\\site-packages\\keras\\engine\\training.py\", line 1051, in train_function  *\n        return step_function(self, iterator)\n    File \"C:\\Users\\Ztyo\\anaconda3\\envs\\env_ybs\\lib\\site-packages\\keras\\engine\\training.py\", line 1040, in step_function  **\n        outputs = model.distribute_strategy.run(run_step, args=(data,))\n    File \"C:\\Users\\Ztyo\\anaconda3\\envs\\env_ybs\\lib\\site-packages\\keras\\engine\\training.py\", line 1030, in run_step  **\n        outputs = model.train_step(data)\n    File \"C:\\Users\\Ztyo\\anaconda3\\envs\\env_ybs\\lib\\site-packages\\keras\\engine\\training.py\", line 889, in train_step\n        y_pred = self(x, training=True)\n    File \"C:\\Users\\Ztyo\\anaconda3\\envs\\env_ybs\\lib\\site-packages\\keras\\utils\\traceback_utils.py\", line 67, in error_handler\n        raise e.with_traceback(filtered_tb) from None\n    File \"C:\\Users\\Ztyo\\anaconda3\\envs\\env_ybs\\lib\\site-packages\\keras\\layers\\regularization\\dropout.py\", line 99, in _get_noise_shape\n        for i, value in enumerate(self.noise_shape):\n\n    TypeError: Exception encountered when calling layer \"dropout_11\" (type Dropout).\n    \n    'int' object is not iterable\n    \n    Call arguments received by layer \"dropout_11\" (type Dropout):\n      • inputs=tf.Tensor(shape=(128, 12, 12, 32), dtype=float32)\n      • training=True\n"
     ]
    }
   ],
   "source": [
    "model.fit(X_train,y_train_split,validation_data=(X_val,y_val),\n",
    "         batch_size=128, epochs=5, callbacks=model_checkpoint,verbose=1)\n",
    "         "
   ]
  },
  {
   "cell_type": "code",
   "execution_count": null,
   "id": "5dda14e8-9d91-4cb8-9eaa-2523354bb8c1",
   "metadata": {},
   "outputs": [],
   "source": []
  }
 ],
 "metadata": {
  "kernelspec": {
   "display_name": "env_ybs",
   "language": "python",
   "name": "env_ybs"
  },
  "language_info": {
   "codemirror_mode": {
    "name": "ipython",
    "version": 3
   },
   "file_extension": ".py",
   "mimetype": "text/x-python",
   "name": "python",
   "nbconvert_exporter": "python",
   "pygments_lexer": "ipython3",
   "version": "3.10.10"
  }
 },
 "nbformat": 4,
 "nbformat_minor": 5
}
